Workbook

Sheet Ficha 1
P1: {=IFS(AND(H11<E15,E11<E15),"7",OR(E11>=E15,H11>=E15,E11=E15=H11),"8",AND(E11>E15,H11>E15),"9")} -> 8
B2: INVESTIGADOR | R2: OBSERVAÇÕES
B3: Nome: | H3: Pontos de Vida | O3: FOTO | S3: =IF(R3="","",VLOOKUP(R3,Regras!D2:E5,2,))
B4: Jogador: | H4: Máx | I4: =ROUNDDOWN((E13+E15)/10,0) -> 0 | L4: Atual
B5: Ocupação: | H5: Pontos de Magia
B6: Idade: | E6: Sexo: | H6: Máx | I6: =L14 -> 0 | L6: Atual | M6: =I6 -> 0
B7: Residência: | H7: Sanidade
B8: Local Nasc: | H8: Máx | J8: Inicial | K8: =K13 | L8: Atual
D10: ATRIBUTOS | S10: =IF(R10="","",VLOOKUP(R10,Regras!A2:B15,2,))
D11: FOR | F11: =ROUNDDOWN(E11/2,0) -> 0 | G11: DES | I11: =ROUNDDOWN(H11/2,0) -> 0 | J11: INT | L11: =ROUNDDOWN(K11/2,0) -> 0 | M11: Combate
F12: =ROUNDDOWN(E11/5,0) -> 0 | I12: =ROUNDDOWN(H11/5,0) -> 0 | L12: =ROUNDDOWN(K11/5,0) -> 0 | M12: Dano extra | O12: {=IFERROR(IFS(AND(2<=E11+E15,E11+E15<=64),"-2",AND(65<=E11+E15,E11+E15<=84),"-1",AND(85<=E11+E15,E11+E15<=124),"",AND(125<=E11+E15,E11+E15<=164),"+1D4",AND(165<=E11+E15,E11+E15<=204),"+1D6",AND(205<=E11+E15,E11+E15<284),"+2D6",AND(285<=E11+E15,E11+E15<=364),"+3D6",AND(365<=E11+E15,E11+E15<=444),"+4D6",AND(445<=E11+E15,E11+E15<=524),"+5D6"),"")}
D13: CON | F13: =ROUNDDOWN(E13/2,0) -> 0 | G13: APA | I13: =ROUNDDOWN(H13/2,0) -> 0 | J13: POD | L13: =ROUNDDOWN(K13/2,0) -> 0 | M13: Corpo | O13: {=IFERROR((IFS(AND(2<=E11+E15,E11+E15<=64),"-2",AND(65<=E11+E15,E11+E15<=84),"-1",AND(85<=E11+E15,E11+E15<=124),"",AND(125<=E11+E15,E11+E15<=164),"1",AND(165<=E11+E15,E11+E15<=204),"2",AND(205<=E11+E15,E11+E15<284),"3",AND(285<=E11+E15,E11+E15<=364),"4",AND(365<=E11+E15,E11+E15<=444),"5",AND(445<=E11+E15,E11+E15<=524),"6")),"")}
F14: =ROUNDDOWN(E13/5,0) -> 0 | I14: =ROUNDDOWN(H13/5,0) -> 0 | L14: =ROUNDDOWN(K13/5,0) -> 0 | M14: Esquivar | N14: =J33 | O14: =ROUNDDOWN(N14/2,0) -> 0
D15: TAM | F15: =ROUNDDOWN(E15/2,0) -> 0 | G15: EDU | I15: =ROUNDDOWN(H15/2,0) -> 0 | J15: Taxa de Movimento | L15: {=IFS(AND(40<=D6,D6<=49),P1-1,AND(50<=D6,D6<=59),P1-2,AND(60<=D6,D6<=69),P1-3,AND(70<=D6,D6<=79),P1-4,AND(80<=D6,D6<=90),P1-5,TRUE,P1)} -> 8 | O15: =ROUNDDOWN(N14/5,0) -> 0
F16: =ROUNDDOWN(E15/5,0) -> 0 | I16: =ROUNDDOWN(H15/5,0) -> 0 | M16: SORTE
S17: 1
B18: PERÍCIAS | S18: {=IFS(R18<>"",VLOOKUP(R18,Regras!G:H,2,), R25<>"",VLOOKUP(R25,Regras!G:H,2,), R32<>"",VLOOKUP(R32,Regras!G:H,2,), TRUE,"")}
C19: Antropologia (1%) | F19: =ROUNDDOWN(E19/2,0) -> 0 | H19: Demolições (01%) [Incomum] | K19: =ROUNDDOWN(J19/2,0) -> 0 | M19: Lutar (Motosseras) (10%) | P19: =ROUNDDOWN(O19/2,0) -> 0
F20: =ROUNDDOWN(E19/5,0) -> 0 | K20: =ROUNDDOWN(J19/5,0) -> 0 | P20: =ROUNDDOWN(O19/5,0) -> 0
C21: Arma de fogo (15%) (Arcos) | F21: =ROUNDDOWN(E21/2,0) -> 0 | H21: Dirigir Automóveis (20%) | K21: =ROUNDDOWN(J21/2,0) -> 0 | M21: Medicina (01%) | P21: =ROUNDDOWN(O21/2,0) -> 0
F22: =ROUNDDOWN(E21/5,0) -> 0 | K22: =ROUNDDOWN(J21/5,0) -> 0 | P22: =ROUNDDOWN(O21/5,0) -> 0
C23: Arma de fogo (10%) (Armas Pesadas) | F23: =ROUNDDOWN(E23/2,0) -> 0 | H23: Direito (05%) | K23: =ROUNDDOWN(J23/2,0) -> 0 | M23: Mergulho (01%) [Incomum] | P23: =ROUNDDOWN(O23/2,0) -> 0
F24: =ROUNDDOWN(E23/5,0) -> 0 | K24: =ROUNDDOWN(J23/5,0) -> 0 | P24: =ROUNDDOWN(O23/5,0) -> 0
C25: Arma de fogo (10%) (Lança-Chamas) | F25: =ROUNDDOWN(E25/2,0) -> 0 | H25: Disfarce (05%) | K25: =ROUNDDOWN(J25/2,0) -> 0 | M25: Mythos de Cthulhu (00%) | P25: =ROUNDDOWN(O25/2,0) -> 0
F26: =ROUNDDOWN(E25/5,0) -> 0 | K26: =ROUNDDOWN(J25/5,0) -> 0 | P26: =ROUNDDOWN(O25/5,0) -> 0
C27: Arma de fogo (10%) (Metralhadora) | F27: =ROUNDDOWN(E27/2,0) -> 0 | H27: Escalar (20%) | K27: =ROUNDDOWN(J27/2,0) -> 0 | M27: Mundo Natural (10%) | P27: =ROUNDDOWN(O27/2,0) -> 0
F28: =ROUNDDOWN(E27/5,0) -> 0 | K28: =ROUNDDOWN(J27/5,0) -> 0 | P28: =ROUNDDOWN(O27/5,0) -> 0
C29: Arma de fogo (20%) (Pistola) | F29: =ROUNDDOWN(E29/2,0) -> 0 | H29: Escutar (20%) | K29: =ROUNDDOWN(J29/2,0) -> 0 | M29: Natação (20%) | P29: =ROUNDDOWN(O29/2,0) -> 0
F30: =ROUNDDOWN(E29/5,0) -> 0 | K30: =ROUNDDOWN(J29/5,0) -> 0 | P30: =ROUNDDOWN(O29/5,0) -> 0
C31: Arma de fogo (20%) (Rifles/Espingardas) | F31: =ROUNDDOWN(E31/2,0) -> 0 | H31: Encontrar (25%) | K31: =ROUNDDOWN(J31/2,0) -> 0 | M31: Navegação (10%) | P31: =ROUNDDOWN(O31/2,0) -> 0
F32: =ROUNDDOWN(E31/5,0) -> 0 | K32: =ROUNDDOWN(J31/5,0) -> 0 | P32: =ROUNDDOWN(O31/5,0) -> 0
C33: Arma de fogo (15%) (Submetralhadora) | F33: =ROUNDDOWN(E33/2,0) -> 0 | H33: Esquivar (metade da DES%) | K33: =ROUNDDOWN(J33/2,0) -> 0 | M33: Nível de Crédito (00%) | P33: =ROUNDDOWN(O33/2,0) -> 0
F34: =ROUNDDOWN(E33/5,0) -> 0 | K34: =ROUNDDOWN(J33/5,0) -> 0 | P34: =ROUNDDOWN(O33/5,0) -> 0
C35: Arqueologia (01%) | F35: =ROUNDDOWN(E35/2,0) -> 0 | H35: Furtividade (20%) | K35: =ROUNDDOWN(J35/2,0) -> 0 | M35: Ocultismo (05%) | P35: =ROUNDDOWN(O35/2,0) -> 0
F36: =ROUNDDOWN(E35/5,0) -> 0 | K36: =ROUNDDOWN(J35/5,0) -> 0 | P36: =ROUNDDOWN(O35/5,0) -> 0
C37: Arremessar (20%) | F37: =ROUNDDOWN(E37/2,0) -> 0 | H37: Hipnose (01%) [Incomum] | K37: =ROUNDDOWN(J37/2,0) -> 0 | M37: Operar Maquinário Pesado (01%) | P37: =ROUNDDOWN(O37/2,0) -> 0
F38: =ROUNDDOWN(E37/5,0) -> 0 | K38: =ROUNDDOWN(J37/5,0) -> 0 | P38: =ROUNDDOWN(O37/5,0) -> 0
C39: Arte e Ofício (05%) (Especializações) | F39: =ROUNDDOWN(E39/2,0) -> 0 | H39: História (05%) | K39: =ROUNDDOWN(J39/2,0) -> 0 | M39: Persuasão (10%) | P39: =ROUNDDOWN(O39/2,0) -> 0
F40: =ROUNDDOWN(E39/5,0) -> 0 | K40: =ROUNDDOWN(J39/5,0) -> 0 | P40: =ROUNDDOWN(O39/5,0) -> 0 | R40: 3,,
C41: Arte e Ofício (05%) (Especializações) | F41: =ROUNDDOWN(E41/2,0) -> 0 | H41: Intimidação (15%) | K41: =ROUNDDOWN(J41/2,0) -> 0 | M41: Pilotar (01%) (Especializações) | P41: =ROUNDDOWN(O41/2,0) -> 0
...

Sheet Regras
A1: Atributos | D1: PONTOS E SANIDADE | G1: PERÍCIAS | I1: Patrimonio | K1: Outras Regras
A2: FORÇA | B2: FOR (Força): jogue 3D6 e multiplique por 5 para gerar o atributo Força. A Força mede o poder muscular de um investigador. Quanto maior for, mais o investigador conseguirá levantar ou se agarrar a algo. Este atributo determina o dano que o investigador causa no combate corpo a corpo. Reduzido a FOR 0, um investigador estará inválido, incapaz de sair da cama. | D2: PONTOS DE VIDA | E2: Pontos de Vida [CON e TAM] Pontos de Vida são usados para medir o dano cumulativo causado a um investigador, personagem não-jogador ou monstro durante o jogo, além de indicar o quanto eles podem permanecer em ação antes de cair devido à dor, exaustão ou morte. Calcule o total de pontos de vida do personagem somando CON e TAM, e dividindo o total por dez (arredondando para baixo as frações). A ficha de investigador foi projetada para ajudar o jogador a acompanhar seus pontos de vida e ferimentos. Anote o Total de Pontos de Vida do investigador na caixa indicada como “Pontos de Vida". | G2: Antropologia | H2: Antropologia (01%) Habilita o usuário a identificar e entender o modo de vida de um indivíduo através da observação. Se o usuário dessa perícia observa outra cultura por algum tempo, estando imerso nela ou utilizando registros precisos sobre uma cultura extinta, então previsões simples podem ser feitas sobre os costumes e a moral de tal cultura, mesmo que as evidências possam estar incompletas. Estudando a cultura por um mês ou mais, o antropólogo começa a entender como ela funciona e, combinando essa perícia com Psicologia, pode prever as ações e crenças daqueles que estão sendo estudados. Exemplos de testes Forçados: ficar mais tempo estudando determinada cultura; viver como um “nativo” por um tempo; assumir um papel ativo em uma cerimônia, rito, etc. Exemplos de fracasso em testes Forçados: ser atacado ou aprisionado pelo povo estudado devido a alguma transgressão de suas leis ou costumes sociais; sofrer graves efeitos colaterais como resultado de ingerir plantas psicotrópicas em uma cerimônia. Se um investigador insano falhar em um teste forçado, ele ou ela se perderá na cultura estudada, como, por exemplo, o personagem fotojornalista de Dennis Hopper no filme Apocalypse Now. | I2: Nível de Crédito | J2: 0: Pobretão - Uma pessoa que sequer pode pagar pelo nível de “pobre” é considerada um pobretão. Acomodações: essa pessoa viveria na rua. Viagem: a pé, pegando carona ou clandestino em um trem ou navio. 1-9: Pobre - Capaz de pagar por um teto qualquer sobre a cabeça e pelo menos uma parca refeição por dia. Acomodações: restrito ao aluguel mais barato ou a um albergue sujo. Viagem: transporte público do tipo mais barato. Qualquer veículo possuído será barato e não confiável. 10-49: Médio - Um nível razoável de conforto, três refeições por dia e uma diversão ocasional. Acomodações: uma casa ou apartamento comum, alugado ou não. Pode ficar em hotéis com preços moderados. Viagem: formas padrão de viagem podem ser usadas, mas não de primeira classe. Em tempos modernos, esta pessoa provavelmente possuiria um carro confiável. 50-89: Abastado - Este nível de riqueza oferece luxo e conforto. Acomodações: uma residência de tamanho considerável, talvez com alguma ajuda doméstica (mordomo, governanta, faxineiro, jardineiro etc.). Possivelmente uma segunda casa no interior ou em outro país. Hospeda-se em hotéis caros. Viagem: primeira classe. Esta pessoa poderia ser proprietária de um carro caro ou equivalente. 90+: Rico - Este nível de riqueza proporciona grande luxo e conforto. Acomodações: uma residência de luxo ou propriedade com abundante ajuda doméstica (mordomo, serviçais, faxineiro, jardineiro etc.). Outras residências no interior e em outros países. Fica nos melhores hotéis. Viagem: primeira classe. Em tempos modernos, essa pessoa seria proprietária de vários carros de luxo. Não há necessidade de se contabilizar gastos com acomodações, comida ou despesas de viagem, desde que os gastos do investigador estejam dentro dos limites de seu padrão de vida. Consulte a Tabela II: Dinheiro e Patrimônio (página 47) caso o investigador deseje fazer compras mais significativas. 99: Ricaço - Como o Rico, mas dinheiro realmente não é problema. Os indivíduos desta categoria estão entre os mais ricos do mundo | K2: Teste de Ideia | L2: Testes de Ideia (INT) O teste de Ideia é diferente de todos os outros. Se você achar que ficou preso e que não sabe para onde seguir com o jogo, então você sempre tem a opção de pedir por um teste de Ideia. Talvez você tenha perdido uma pista importante ou simplesmente não tenha adivinhado completamente as coisas. O teste de Ideia combina os poderes dedutivos, a memória e a intuição de seu investigador, concedendo uma pista que colocará o jogo de volta a seus trilhos. Mas tenha cuidado — quanto mais óbvia for a pista, maior a probabilidade de você se ver em maus lençóis no momento em que descobri-la.
A3: CONSTITUIÇÃO | B3: CON (Constituição): jogue 3D6 e multiplique por 5 para gerar o atributo Constituição. A Constituição representa saúde, vigor e vitalidade. Venenos e doenças podem desafiar diretamente a constituição de um investigador. Investigadores com constituição alta muitas vezes têm mais pontos de vida — o que é melhor para resistir a ferimentos e ataques. Lesões físicas graves ou ataques mágicos podem diminuir esse atributo, e, se a Constituição chegar a zero, o investigador morre. | D3: PONTOS DE MAGIA | E3: Os pontos de Magia devem (na maioria dos casos) ser gastos para lançar feitiços, bem como para energizar artefatos, carregar portais mágicos e assim por diante. Um investigador começa o jogo com pontos de Magia iguais a um quinto de seu POD; no entanto, cultistas e feiticeiros poderosos muitas vezes têm quantidades maiores de pontos para utilizar. Quando um indivíduo estiver sem pontos de Magia, qualquer gasto adicional é reduzido diretamente de seus pontos de vida. A perda de pontos de vida dessa forma se manifesta como um dano físico cuja forma é determinada pelo Guardião — talvez chagas e cortes se abram no corpo, bolhas surjam na pele ou sangue saia pelos olhos ou ouvidos. Gastar ou sacrificar pontos de Magia ou pontos de POD exige apenas a vontade de seu dono. Fazê-lo pode deixar sensações de prazer misturadas com arrependimento, um entorpecimento na alma, ou pode não trazer qualquer consequência notável. A essência ou energia do conjurador é canalizada para alimentar o feitiço. | G3: Armas de Fogo | H3: (% variável) Abrange todos os tipos de armas de fogo, bem como arcos e bestas. Você pode gastar pontos de perícia para comprar qualquer especialização. A perícia genérica “Armas de Fogo” não pode ser comprada. Escolha especializações apropriadas para a ocupação e os antecedentes do seu investigador. Nota: sendo uma perícia de combate, não pode ser forçada. Especializações em Armas de Fogo: Arcos (15%): uso de arcos e bestas, desde arcos longos medievais até arcos compostos modernos de alta potência. Armas Pesadas (10%): use para lançadores de granadas, mísseis antitanque, etc. Lança-chamas (10%): armas que projetam um fluxo de líquido ou gás inflamável em chamas. Podem tanto ser transportadas pelo operador ou armadas em um veículo. Metralhadoras (10%): armas que disparam rajadas a partir deu m bipé ou tripé armado. Para disparos únicos a partir de um bipé, use a perícia Rifles. As diferenças entre fuzis de assalto, submetralhadoras e metralhadoras leves são tênues hoje em dia. Pistolas (20%): use para todas as armas de fogo do tipo pistola quando estiver disparando tiros simples. Para pistolas-metralhadoras (MAC-11, Uzi, etc.) em jogos ambientados na Era Moderna, use a perícia Submetralhadoras quando estiver disparando rajadas. Rifles/Espingardas (25%): com esta perícia pode-se usar qualquer tipo de rifle (seja de alavanca, ferrolho ou semiautomático) ou arma de cartuchos de projéteis múltiplos. Já que o disparo de uma Espingarda se espalha, a chance de o usuário errar não diminui com a distância, mas o dano causado sim. Quando um fuzil de assalto disparar em modo de tiro único (ou múltiplos disparos simples), use essa perícia. | I3: Dinheiro | J3: Dinheiro: Não é necessariamente carregado com a pessoa. O Guardião pode perguntar onde ele está sendo guardado. Por exemplo, se o investigador estiver viajando para o exterior, ele o está mantendo em sua carteira ou há alguém em casa que pode lhe transferir dinheiro quando solicitado? Isso terá um impacto caso o investigador seja roubado ou perca seu equipamento. | K3: Teste de Inteligência | L3: Testes de Inteligência (INT) Embora os teste de Inteligência usem o mesmo atributo que um teste de Ideia (INT), essas duas jogadas representam coisas diferentes. Um teste de Ideia é usado quando você não sabe qual será seu próximo passo em uma investigação. Já um teste de Inteligência é feito quando seu investigador está tentando resolver um quebra- cabeças intelectual de algum tipo. Isso pode incluir resolver palavras cruzadas, responder a um enigma ou decodificar uma mensagem enigmática.
A4: DESTREZA | B4: DES (Destreza): Jogue 3D6 e multiplique por 5 para gerar o atributo Destreza. Investigadores com valores altos de Destreza são mais rápidos, mais ágeis e mais fisicamente flexíveis. Um teste de DES pode ser feito para se agarrar em algum lugar e evitar uma queda, para se mover mais rápido do que um adversário ou para realizar alguma tarefa delicada. Um investigador com zero de DES é descoordenado e incapaz de executar tarefas físicas. Em combate, o personagem com a DES mais alta age primeiro. | D4: SANIDADE | E4: Os pontos de Sanidade devem ser acompanhados cuidadosamente, pois seu valor pode aumentar ou diminuir ao longo do jogo. Quando os investigadores encontram uma situação que ameaça a sanidade, o Guardião pode pedir um teste de Sanidade. Cada jogador cujo investigador vivencia tal fonte de horror deve jogar 1D100. Uma jogada igual ou menor que o número atual de pontos de Sanidade do investigador é um sucesso. Dados de bônus e dados de penalidade não são aplicados a testes de Sanidade . Um teste bem-sucedido significa que o investigador não perde nenhum ponto de Sanidade, ou que perde apenas uma quantidade mínima. Um fracasso em um teste de Sanidade sempre significa que o investigador perde pontos de Sanidade. A quantidade perdida depende do feitiço, livro, entidade ou situação encontrada. | G4: Arqueologia | H4: Arqueologia (01%) Permite datar e identificar artefatos de culturas passadas e detectar falsificações. Garante conhecimento especializado quanto à organização e escavação de um sítio arqueológico. Ao inspecionar um sítio arqueológico, o usuário pode deduzir os propósitos e costumes daqueles que abandonaram os objetos. Antropologia poderia ajudar nisso. Antropologia poderia ajudar nisso. Arqueologia também ajuda a identificar a escrita de idiomas humanos extintos. Exemplos de testes Forçados: gastar mais tempo estudando o sítio ou objeto; realizar mais pesquisas; consultar outro especialista. Exemplos de fracasso em testes Forçados: o sítio é prejudicado, tendo achados arruinados devido à incompetência, vandalismo ou roubo; alguma autoridade superior tira o sítio ou as descobertas de seu controle; a publicidade leva ao roubo de descobertas. Se um investigador insano falhar em um teste forçado, ele ou ela continua escavando cada vez mais fundo — a verdade está em algum lugar lá embaixo. | I4: Patrimônio | J4: Patrimônio: O patrimônio consiste nas coisas que seu investigador possui no início do jogo, e o valor em dólares no gráfico representa o valor total de tais coisas. O jogador deve anotar o valor em dólares e decidir o que ele representa — geralmente propriedades ou investimentos — ou talvez ações em uma empresa. A lista padrão de posses está incluída nos vários escopos dos padrões de vida. Se o seu padrão de vida inclui uma casa e um carro, estas coisas constituem parte de seu patrimônio. | K4: Teste de Saber | L4: Testes de Saber (EDU) Todo mundo sabe um pouco sobre diferentes tópicos. O teste de Saber representa o que está armazenado no sótão intelectual do cérebro. O investigador pode ser capaz de identificar uma determinada espécie de árvore (sem ter estudado Botânica), lembrar a geografia do Tibete (sem um teste de Navegação) ou saber quantas patas aracnídeos têm (e possuir apenas um único ponto em Biologia).
A5: APARÊNCIA | B5: APA (Aparência): Jogue 3D6 e multiplique por 5 para gerar o atributo Aparência. A Aparência mede tanto a atratividade física quanto a personalidade. Uma pessoa com uma APA alta é encantadora e simpática, mas pode não ser bonita no sentido convencional. Um investigador com APA 0 é terrivelmente feio ou alguém com uma atitude completamente detestável, provocando comentários e comoção onde quer que vá. A APA pode ser útil em encontros sociais ou quando se tenta causar uma boa impressão. | D5: SANIDADE MÁXIMA | E5: A ameaça de insanidade em Chamado de Cthulhu caracteriza o Mythos de Cthulhu de uma forma que não permite concessões. Expostos a eles, poucos humanos sãos escolhem livremente o Mythos, pois o Mythos é intrinsecamente repugnante e nefasto. A conexão entre os pontos de Sanidade e os pontos na perícia Mythos de Cthulhu enfatiza o poder do Mythos, que corrompe e arruína por proximidade e associação. Os pontos de Sanidade de um investigador podem aumentar e diminuir durante o jogo; no entanto, nunca podem ultrapassar o valor máximo de Sanidade do personagem. Cada investigador possui um valor máximo de pontos de Sanidade, que começa em 99. Conhecimento do Mythos de Cthulhu sempre diminui os pontos máximos de Sanidade de um investigador. Os pontos máximos de Sanidade são iguais a 99 menos os pontos atuais de Mythos de Cthulhu (99- a perícia Mythos de Cthulhu). Ao ganhar pontos em Mythos de Cthulhu, o jogador deve diminuir a Sanidade máxima do investigador na mesma quantidade. | G5: Arremessar | H5: Arremessar (20%) Use Arremessar para acertar um alvo com um objeto ou com a parte correta de um objeto (como a lâmina de uma faca ou machadinha). Um objeto que caiba na mão e seja de peso razoável (ou uma arma projetada para ser arremessada) pode ser atirado até uma distância igual a FOR dividido por 5 metros. Se o teste de Arremessar falhar, o objeto cai a alguma distância aleatória do alvo. O Guardião deve comparar quão próximo de um sucesso foi o teste e escolher uma distância que pareça apropriada entre objeto arremessado e alvo. A perícia Arremessar é usada em combate quando se lançam facas, pedras, lanças, granadas ou bumerangues. Uma vez que um item tenha sido arremessado, ele estará literalmente fora das mãos do investigador e, portanto, não há nada que o jogador possa fazer para justificar um teste Forçado. Se houver múltiplos projéteis disponíveis, não houver risco relacionado ao fracasso e for apenas uma questão de tempo até o investigador ser bem-sucedido, não sendo preciso fazer testes. Exemplos de testes Forçados: gastar mais tempo para avaliar a distância ou aguardar algum tempo por condições mais favoráveis; colocar toda força no arremesso e lançar-se para frente junto ao movimento; lançar vários itens em rápida sucessão, esperando que algum deles atinja o alvo; correr bastante antes do arremesso e arriscar que o impulso tomado faça você cair do barranco. Exemplos de fracasso em testes Forçados: você arremessa o objeto em um companheiro enquanto tropeça e cai, batendo a cabeça contra as pedras pontudas; você arremessa forte demais e o objeto voa por cima do grande muro da igreja e cai no cemitério; a banana de dinamite escorrega de sua mão — você procura em vão, mas não consegue vê-la presa ao seu capuz, e só então sente o cheiro do pavio queimando. Se um investigador insano falhar um teste forçado, ele ou ela se recusará a soltar o item que deveria ser arremessado. | K5: Teste de Sorte | L5: Testes de Sorte Testes de Sorte se aplicam a circunstâncias externas. Se outra perícia ou atributo puder ser usado, então um teste de Sorte não é apropriado. Por exemplo, se você estiver na velha casa quando as luzes se apagarem e quiser determinar se há alguma vela nas gavetas da cozinha — não há nenhuma perícia que possa determinar isso. O Guardião poderia simplesmente decidir, ou então pode deixar tudo para a Sorte. Como jogador, você vai querer que seu investigador tenha boa sorte, mas como este é um jogo de terror, espere que o Guardião fique mais do que feliz em compensar com má sorte. A Sorte também pode ser útil em combate quando você quiser encontrar uma arma improvisada útil. O Guardião pode permitir que um teste de Sorte determine existe algum cano de chumbo ou taco de beisebol por perto. A Sorte é um valor que nunca é afetado por dados de penalidade ou de bônus, e os testes são feitos apenas contra seu valor atual.
A6: TAMANHO | B6: TAM (Tamanho): Jogue 2D6+6 e multiplique por 5 para gerar o atributo Tamanho. O Tamanho representa altura e peso, ambos em um único número. Para enxergar por sobre um muro, espremer-se através de uma pequena abertura ou até mesmo para saber de quem é a cabeça que está despontando da grama, use o tamanho. O tamanho ajuda a determinar os pontos de vida, o dano extra e o Corpo. Pode-se diminuir o TAM para indicar a perda de um membro, embora reduzir a DES seja a solução mais frequente. Provavelmente, se os investigadores perderem todos os pontos de TAM, eles desaparecem — só os deuses sabem para onde! | G6: Arte e Ofício | H6: Arte e Ofício (Especializações) (05%) A ficha de investigador contém espaços em branco para especializações nesta perícia, como, por exemplo: Atuação, Barbearia, Carpintaria, Sapataria, Culinária, Dança, Belas Artes, Falsificação, Dançarino de Morris, Cantor de Ópera, Pintura e Decoração, Fotografia, Olaria, Escultura, Escritor, Marcenaria Muitos desses exemplos são perícias diretamente ligadas a uma profissão, mas a perícia pode ser apenas uma atividade de lazer. Você pode gastar pontos de perícia para comprar qualquer especialização. A perícia genérica “Arte e Ofício” não pode ser comprada. Essa perícia permite a criação ou conserto de um item — normalmente exigindo equipamento e tempo, a serem determinados pelo Guardião, se necessário. Em situações em que a gradação de sucesso pode ser apropriada, níveis maiores de sucesso indicam itens de maior qualidade e/ou precisão. Uma perícia de arte ou ofício também pode ser usada para duplicar ou falsificar um objeto. Neste caso, o nível de dificuldade dependeria da complexidade e em quão distinta é a peça original. Para falsificar documentos, é utilizada uma especialização específica: (Falsificação). Um teste bem-sucedido pode fornecer informações sobre um item, como, por exemplo, onde ou quando ele poderia ter sido confeccionado, alguma informação sobre sua história ou técnica de fabricação, ou então sobre quem poderia tê-lo produzido. Possuir uma especialidade dessa perícia representa ter uma ampla gama de conhecimentos dentro de um campo particular — conhecimento do assunto, de sua história e de praticantes contemporâneos, bem como a capacidade de pôr em prática suas técnicas. Exemplos de testes Forçados: retrabalhar o objeto, peça ou composição do zero; realizar mais pesquisas; consultar outro especialista. Exemplos de fracasso em testes Forçados: uma grande quantidade de tempo e dinheiro é desperdiçada com uma tentativa fracassada; a audiência ou cliente ficam ofendido ou fisicamente feridos por algum aspecto do seu trabalho; os críticos atacam a sua obra e ninguém deseja mais os seus serviços. Se um investigador insano falhar em um teste forçado, ele ou ela cria um trabalho transgressivo que choca e provoca reações violentas — talvez somente os mais decadentes possam apreciá-lo. Exemplos de Especializações em Arte e Ofício Atuação (05%): O intérprete é treinado em atuação teatral e/ou cinematográfica (na era moderna, isso também pode incluir televisão), capaz de adotar uma persona, memorizar roteiros e utilizar a maquiagem de palco/filme para alterar sua aparência. Veja Disfarce. Belas Artes (05%): O artista é talentoso na arte da pintura (óleo, acrílico, aquarela), bem como em fazer esboços com lápis, giz ou pastel. Embora obras de arte sérias possam levar muitos dias ou meses para serem concluídas, o artista pode rapidamente desenhar esboços, objetos e pessoas. A perícia também denota uma familiaridade com o “mundo da arte”, e o personagem pode ser capaz de determinar obras, escola e história de um determinado artista. Falsificação (05%): Adepto dos detalhes precisos, o usuário pode produzir documentos falsos de alta qualidade, seja a caligrafia de uma pessoa, um formulário ou licença burocrática, ou a duplicação de um tomo. O falsificador precisará de materiais adequados (tintas, papel etc.), bem como de um objeto original do qual copiar. Um teste bem-sucedido indica que a falsificação será considerada verdadeira em inspeções rápidas e costumeiras. Alguém que gaste tempo para examinar minuciosamente a falsificação usaria a perícia Avaliação (resistida pela perícia do forjador) para determinar se a falsificação pode ser notada. Fotografia (05%): Abrange tanto fotografia comum quanto a cinematográfica. Esta perícia permite tirar fotos claras, desenvolvê-las adequadamente e melhorar a definição de detalhes que possam estar difusos. Na década de 1920, o usuário é capaz de preparar o material químico necessário para fazer flash em pó (ver Fotografia Perigosa, página 173). Atualmente, a perícia se estende para cobrir câmeras de vídeo, equipamentos de reprodução de vídeo, fotografia e edição digital, sendo o usuário experiente na manipulação de imagens digitais. Versões radicalmente diferentes podem ser criadas a partir de uma fonte original, como alterar a localização de uma pessoa em uma foto, com quem ela está e o que está fazendo. Essa perícia também permite perceber que uma imagem foi manipulada. Fotos corriqueiras não exigem testes. Testes seriam necessários apenas para se obter fotografias de uma pessoa que não sabe estar sendo fotografada, ou conseguir capturar detalhes minuciosos — especialmente a longas distâncias, em movimento ou com pouca luz. Essa perícia também pode permitir que o investigador determine se uma fotografia foi adulterada ou forjada, bem como o ângulo e a posição a partir dos quais uma foto foi tirada. | K6: Treinamento | L6: Treinamento Um investigador pode estudar ou treinar por quatro meses e ganhar uma verificação de melhoria para uma perícia. Isso é testado durante a fase de desenvolvimento dos investigadores (ver página 94, Livro Básico de Chamado de Cthulhu). Uma verificação de melhoria ocorre automaticamente ao concluir com sucesso um segmento de treinamento. Mas, tenha em mente que se o investigador se aventurar muitas vezes durante um semestre, isso invalidará o seu treinamento ou aprendizado em sala de aula durante o período. *Alguns cursos de treinamento podem durar menos de quatro meses, com alguns ocorrendo ao longo de alguns dias ou semanas de treinamento intensivo. Nesses, o Guardião pode dizer que o treinamento foi suficiente para justificar uma verificação de melhoria.
A7: INTELIGÊNCIA | B7: INT (Inteligência): Jogue 2D6+6 e multiplique por 5 para gerar o atributo Inteligência. A Inteligência representa o quão bem os investigadores aprendem, lembram, analisam informações e resolvem enigmas complexos. Um investigador com INT zero é um idiota balbuciante e babão. A inteligência determina a quantidade de pontos de perícia de Interesses Pessoais (multiplique INT ×2) atribuída a um novo investigador (ver Interesses Pessoais, página 50). A INT também atua como o valor para ambos os testes de Ideia e Inteligência. Se a quantidade de INT parecer contradizer outro atributo, esta é outra oportunidade de interpretação e melhor definição de seu investigador. Por exemplo, um investigador com EDU alta e INT baixa pode ser um professor pedante ou um artista de feira, alguém que conhece os fatos, mas não seus significados. Por outro lado, uma INT alta com EDU baixa pode significar ignorância — como um menino de fazenda não escolarizado, novo na Cidade Grande —, porém essa pessoa não seria estúpida. | G7: Artilharia | H7: Artilharia (01%) [Incomum] Esta perícia denota algum treinamento e experiência militar. O usuário tem experiência na operação de armas usadas em campo de guerra: é capaz de trabalhar em uma “tripulação” ou “destacamento” para operar equipamento que utilize calibres maiores do que o das armas pessoais. Muitas armas desta natureza são muito grandes para serem operadas por uma única pessoa, então ou um indivíduo não consegue usar a arma sem uma equipe, ou o nível de dificuldade para operá-la deveria ser maior (a critério do Guardião, dependendo da arma). Existem várias especializações, dependendo do período em que o jogo está ambientado, podendo incluir canhões, morteiros e lança-mísseis. Nota: sendo uma perícia de combate, não pode ser forçada | K7: Exame de Realidade | L7: Fazendo Exames da Realidade Seu investigador está propenso a ter delírios enquanto está louco e não pode mais confiar em seus sentidos. No jogo, a única forma de saber o que seu investigador está vendo e ouvindo é através do que o Guardião está lhe dizendo. Se você não pode confiar em seus sentidos, então, na verdade, você não pode confiar no que o Guardião está dizendo que seu personagem percebe. O Guardião pode dizer um carniçal salta em cima de seu investigador insano; no entanto, o monstro pode ser apenas um sem-teto pedindo uns trocados. Se você quiser sacudir a cabeça e recobrar seus sentidos, esforçando-se para ver através do que pode ser uma alucinação insana, simplesmente diga ao Guardião que você quer fazer um teste de Exame da Realidade. Você sempre tem a opção de lutar contra a loucura — mas se você falhar no exame da realidade, a loucura vai contra-atacar!
A8: PODER | B8: POD (Poder): Jogue 3D6 e multiplique por 5 para gerar o atributo Poder. Poder indica a força de vontade: quanto maior o POD, maior a aptidão mágica e a resistência à magia. Um investigador com POD zero é apático e sem “propósito”, além de ser incapaz de usar magia. Salvo quando indicado o contrário, o POD perdido durante o jogo não pode ser recuperado. Os pontos de Sanidade (SAN) começam iguais ao POD do personagem. O POD também determina o número de “pontos de magia” do personagem, os quais, ao contrário do POD, podem ser gastos e regenerados durante o jogo. A quantidade de Pontos de Magia começa igual a um quinto do POD. O POD de personagens e investigadores comuns raramente muda. No entanto, aqueles versados nos mistérios da magia do Mythos de Cthulhu podem conseguir aumentar seu POD. | G8: Conhecimento | H8: Conhecimento (01%) (Especializações) [Incomum] Esta perícia representa a compreensão do personagem sobre algum assunto que está fora dos limites normais do conhecimento humano. As especializações de Conhecimento devem ser específicas e incomuns, tais como: • Conhecimento Sobre Sonhos • Conhecimento do Necronomicon (a história do livro) • Conhecimento Ufológico • Conhecimento Sobre Vampiros • Conhecimento Sobre Lobisomens • Conhecimento Yaddithiano Quando o Guardião deseja testar o conhecimento de um investigador acerca de algo que está dentro dos limites de uma dessas áreas de Conhecimento, mas o investigador não possui a especialização de Conhecimento apropriada, o Guardião pode permitir que outra perícia (mais geral) seja usada, mas exigir um nível de sucesso maior. Por exemplo, se o Guardião estiver testando o conhecimento de um investigador moderno sobre abduções alienígenas na década de 80, poderia pedir um sucesso Regular usando Conhecimento Ufológico ou um sucesso Sólido usando História. As perícias de Conhecimento também são usadas como um método sucinto do Guardião repassar o conhecimento específico possuído por um personagem não-jogador. O conhecimento geral de um personagem costuma ser representado pelo atributo EDU e por perícias específicas, como História ou Mythos de Cthulhu. O Guardião deve decidir quando a perícia Conhecimento deve ser incorporada ao jogo — geralmente apenas quando uma área específica de conhecimento especializado é central para a campanha.
A9: EDUCAÇÃO | B9: EDU (Educação): Jogue 2D6+6 e multiplique por 5 para gerar o atributo Educação. A Educação é uma medida para o conhecimento formal e factual possuído pelo investigador, bem como um indicativo do tempo que o investigador gastou na educação formal. A EDU mede a informação retida, não a aplicação inteligente de tal informação (ver Inteligência, acima). Um investigador sem EDU seria como um bebê recém-nascido ou um amnésico — sem conhecimento do mundo, provavelmente muito curioso e crédulo. Uma EDU de 60 sugere que o investigador é um graduado no ensino médio, enquanto uma pontuação de cerca de 70 indica uma pessoa com alguns anos de faculdade. Aqueles com uma EDU maior que 80 muito provavelmente realizaram trabalho de nível de pós-graduação e possuem um diploma, como esperado de uma pessoa que tenha estado em uma universidade de algum tipo. Note que, às vezes, uma pessoa com uma Educação alta pode não ter sido necessariamente educada em escolas e faculdades tradicionais, mas pode ser autodidata e possuir uma natureza altamente estudiosa e observadora. A EDU é um fator na determinação da quantidade pontos de Perícias Ocupacionais (ver Perícias Ocupacionais, página 49) que um investigador começa e representa a porcentagem inicial do investigador na perícia Língua Nativa (ver página 109). A EDU também é usada para Testes de Saber. | G9: Avaliação | H9: Avaliação (01%) Usada para estimar o valor de um item em particular, incluindo a qualidade, material utilizado e mão de obra. Quando relevante, o usuário dessa perícia pode identificar a idade do item, avaliar sua relevância histórica e detectar falsificações. Exemplos de testes Forçados: verificar a validade de um item com outro especialista; realizar testes; pesquisar mais sobre um item. Exemplos de fracasso em testes Forçados: acidentalmente arruinar o item em questão; chamar a atenção de outras pessoas para o item, levando ao seu roubo; ativar o item de alguma forma. Se um investigador insano falhar em um teste forçado, ele ou ela poderia destruir o item, acreditando que seja amaldiçoado; ou então pode considerar o item como sua salvação pessoal e se recusar a cedê-lo para qualquer outra pessoa.
A10: SORTE | B10: O Guardião pode exigir testes de Sorte quando circunstâncias externas à competência dos investigadores estiverem em questão e também ao determinar a mão caprichosa do destino. Se uma perícia ou atributo for aplicável a uma situação, então esta deve ser usada em vez de Sorte. Se o Guardião pedir um teste Coletivo de Sorte, o jogador cujo investigador tem o menor valor de Sorte (dentre os presentes na cena) deve fazer o teste. Se algo ruim deve acontecer com um membro do grupo, o Guardião pode simplesmente perguntar quem tem a pontuação de Sorte mais baixa naquele momento e fazer com que tal indivíduo sofra o infeliz evento. | G10: Cavalgar | H10: Cavalgar (05%) Esta perícia destina-se a ser usada com cavalos de montaria, burros ou mulas, e concede conhecimentos sobre o cuidado básico de animais de equitação, equipamentos de equitação e como lidar com a montaria durante um galope ou em terreno difícil. Se uma montaria inesperadamente empinar ou tropeçar, a chance do cavaleiro permanecer montado é igual à sua perícia Cavalgar. Cavalgar usando sela lateral aumenta o nível de dificuldade em um nível. Uma montaria desconhecida (como um camelo) pode ser montada com sucesso, mas o nível de dificuldade seria maior. Se um investigador cair de sua montaria, seja porque o animal fraquejou, caiu ou morreu (ou porque ele falhou em um teste forçado de Cavalgar), pelo menos 1D6 pontos de vida são perdidos no acidente — embora um teste de Saltar possa negar essa perda. Exemplos de testes Forçados: chicotear ou forçar a montaria agressivamente — talvez forçar o cavalo a saltar sobre um barranco ou uma vala grande; assumir o risco e continuar montado em vez de saltar do animal quando um problema se aproxima. Exemplos de fracasso em testes Forçados: o cavaleiro é arremessado da montaria e recebe dano de queda; a montaria é ferida; o pé do cavaleiro enrola nos estribos e ele acaba sendo arrastado por certa distância. Se um investigador insano falhar em um teste Forçado, ele ou ela fica obcecado pelo animal.
A11: DANO EXTRA E CORPO | B11: Todos os investigadores possuem dois atributos secundários conhecidos como “Dano Extra” (DX) e Corpo. Criaturas e humanos maiores e mais fortes causam mais dano físico do que seus semelhantes mais fracos. Para determinar o dano extra, some FOR e TAM e procure o total na Tabela I: Dano Extra e Corpo. Cada intervalo de resultados correlaciona-se com um modificador ou jogada de dados. O Corpo é determinado usando-se os mesmos parâmetros. Para combate corpo a corpo, adicione o modificador de Dano Extra indicado ou faça as jogadas apropriadas para todos os golpes do personagem, seja usando uma arma natural, como um punho, ou uma arma corpo a corpo, como um porrete ou uma faca. O Corpo é usado em manobras de luta e perseguições, e também para dar uma sensação de escala. Nota: O dano extra não é aplicado a ataques de armas de fogo | G11: Charme | H11: Charme (15%) Charme assume muitas formas, incluindo atração física, sedução, lisonja ou simplesmente uma personalidade calorosa. O Charme pode ser usado para fazer alguém agir de determinada maneira, mas não de uma forma completamente contrária ao comportamento normal dessa pessoa. Charme é resistido pelas perícias Charme ou Psicologia. Charme pode ser usado para barganhar, para diminuir o preço de itens ou serviços. Se o teste for bem-sucedido, o vendedor é conquistado e ele pode muito bem reduzir um pouco os preços. Exemplos de testes Forçados: lisonjear abertamente o alvo; dar um presente caro; construir confiança compartilhando um segredo. Lembre-se que a questão é ser “charmoso”: se o investigador começar a agir de outro modo, o Guardião pode pedir que uma perícia diferente seja usada; se ameaças forem usadas, pode tornar-se Intimidação; ou se houver uma discussão prolongada, pode tornar-se Persuasão. Alternar de uma para outra para ganhar um segundo teste ainda constitui um teste Forçado. Exemplos de fracasso em testes Forçados: o alvo se ofende e não quer mais falar com você; o alvo está associado de alguma forma com inimigos seus e, apesar de colaborar com você, também passa informações sobre você; um terceiro elemento intercede para evitar que você flerte com a garota dele. Se um investigador insano falhar em um teste forçado ele ou ela fica loucamente apaixonado pelo alvo e agirá como se o alvo tivesse conjurado com sucesso um feitiço de Dominação (ver Livro de Regras de Chamado de Cthulhu) sobre eles.
A12: ESQUIVAR | B12: Esquivar (metade da DES%) Permite que um investigador instintivamente evite golpes, objetos atirados contra ele, e coisas do gênero. Um personagem pode tentar se esquivar quantas vezes quiser em uma rodada de combate (mas apenas uma vez contra cada ataque específico). A perícia Esquivar pode ser aprimorada através da experiência, como outras perícias. Se um ataque puder ser visto, um personagem pode tentar se esquivar dele. É impos_x0002_sível esquivar-se de balas porque elas não podem ser vistas quando estão em movimento; o melhor que um personagem pode fazer é realizar uma ação evasiva que o torne mais difícil de ser atingido (ver as regras de Buscando Cobertura no Livro de Regras de Chamado de Cthulhu). Nota: sendo uma perícia de combate, não pode ser forçada. | G12: Chaveiro | H12: Chaveiro (01%) Um perito em Chaveiro pode abrir portas de carro, fazer ligações diretas em automóveis, destravar janelas de bibliotecas, resolver caixas-segredo chinesas e desativar sistemas de alarme comerciais comuns. O usuário pode consertar fechaduras, fazer chaves ou abrir fechaduras com a ajuda de chaves mestras, gazuas e outras ferramentas. Fechaduras especialmente difíceis podem ter um nível de dificuldade maior. Exemplos de testes Forçados: desmontar completamente a fechadura; demorar mais tempo; forçar o mecanismo. Exemplos de fracasso em testes Forçados: a fechadura é danificada para além do conserto (talvez sua gazua tenha se quebrado dentro dela); você quebra a caixa-segredo (talvez apenas quebrá-la a fará abrir-se, agora); você ativa um alarme, ou faz barulho suficiente para que alguém ou algo venha checar... Se um investigador insano falhar em um teste forçado, ele ou ela desiste da tranca em questão e percebe o propósito mais elevado de destrancar sua própria mente; um véu foi levantado de seus olhos, e ele agora vê o mundo de uma nova forma que faz todo o sentido para ele, mas que não faz qualquer sentido para ninguém de mente sã.
A13: Taxa de Movimento | B13: Taxa de Movimento (MOV) Um investigador pode se mover, em uma rodada, uma quantidade de metros até cinco vezes o seu atributo MOV. Se tanto DES quanto FOR tiverem valores menores que TAM: MOV 7 Se FOR ou DES for maior ou igual ao TAM, ou se os três forem iguais: MOV 8 Se FOR e DES forem ambas maiores do que TAM: MOV 9 | G13: Ciências | H13: Ciências (Especializações) (01%) A habilidade prática e teórica com uma especialidade científica sugere algum grau de educação e treinamento formais, embora um cientista amador autodidata também seja uma possibilidade. O entendimento e o escopo são limitados pela era do jogo. Você pode gastar pontos de perícia para comprar qualquer especialização. A perícia genérica “Ciência” não pode ser comprada. Cada especialização cobre uma determinada disciplina e a lista fornecida não é exaustiva. Muitas especialidades se cruzam e se sobrepõem, por exemplo, Matemática e Criptografia, Botânica e Biologia, Química e Farmácia. Quando um personagem não tem a especialização óbvia, pode fazer o teste usando uma especialização aparentada, mas com o nível de dificuldade aumentado (ou usando um dado de penalidade), a critério do Guardião. Exemplos de testes Forçados: passar mais tempo estudando; realizar pesquisas adicionais (talvez em um laboratório melhor equipado); consultar outro especialista; correr riscos. Exemplos de fracasso em testes Forçados: o experimento dá completamente errado, causando problemas imprevistos (explosão, fogo, choque elétrico, expulsão para a sexta dimensão, etc.); você interpreta mal as informações e prepara as fórmulas do pó “mágico” incorretamente, com resultados desastrosos. Se um investigador insano falhar em um teste forçado, ele ou ela começa a explorar um aspecto de “ciência estranha” relacionado à sua especialização. Isso pode acabar levando a resultados reais, semelhantes aos de Crawford Tillinghast (da história Do Além, de Lovecraft). Especializações de Ciência: Astronomia (01%): O usuário sabe como identificar quais estrelas e planetas podem ser vistos em um determinado dia ou hora do dia ou da noite, quando ocorrem eclipses e chuvas de meteoros, e os nomes de estrelas importantes. Esta perícia também garante conhecimento sobre as percepções atuais quanto à vida em outros planetas, a existência ou a formação de galáxias, e assim por diante. Um acadêmico pode ser capaz de calcular órbitas, discutir ciclos de vida estelares e (nos dias atuais), ter conhecimento de astronomia infravermelha ou de interferometria. Biologia (01%): O estudo da vida e dos organismos vivos, incluindo citologia, ecologia, genética, histologia, microbiologia, fisiologia e assim por diante. Com essa perícia, pode-se desenvolver uma vacina contra alguma hedionda bactéria do Mythos, isolar as propriedades alucinógenas de alguma planta da selva ou realizar análises de sangue e/ou matéria orgânica. Botânica (01%): O estudo da vida vegetal, incluindo classificação de espécies, estrutura, crescimento, reprodução, propriedades químicas, princípios evolutivos, doenças e microscopia. Subdisciplinas da botânica incluem agronomia, silvicultura, horticultura e paleobotânica. Com essa perícia, pode-se identificar as propriedades de uma planta em particular (se é venenosa, comestível ou psicotrópica, por exemplo) e seus usos particulares. Criptografia (01%): O estudo de códigos e línguas secretas desenvolvidas por uma ou mais pessoas para ocultar o conteúdo de uma conversa ou mensagem. Um ramo especializado da matemática, essa perícia permite a identificação, criação e/ou decifração de um código. Os códigos geralmente são escritos, mas podem assumir outras formas, como uma mensagem escondida em uma composição musical, arte gráfica ou código de computador (em ambientações modernas). Quebrar um código pode ser um trabalho meticuloso, muitas vezes exigindo uma longa pesquisa e os numerosos processamentos numéricos. Ciência Forense (01%): A análise e identificação de evidências. Normalmente associada à investigação de cenas de crime (exame de impressões digitais, DNA, cabelo e fluidos corporais) e trabalhos laboratoriais, a fim de determinar os acontecimentos e fornecer testemunhos profissionais e evidências legais. Engenharia (01%): Embora tecnicamente não seja uma ciência, é agrupada aqui por conveniência. A ciência trata da identificação de certos fenômenos (através da observação e registro), enquanto que a engenharia aproveita tais descobertas e as utiliza para produzir aplicações práticas como máquinas, estruturas e materiais. Farmácia (01%): O estudo de compostos químicos e seu efeito em organismos vivos. Tradicionalmente, isso tem envolvido a formulação, criação e administração de medicamentos (seja um curandeiro administrando uma combinação de ervas ou um farmacêutico moderno operando um laboratório). A aplicação dessa perícia garante o uso seguro e efetivo de medicamentos, incluindo sintetizar ingredientes, identificar toxinas e conhecer possíveis efeitos colaterais. Física (01%): Concede a compreensão teórica da pressão, materiais, movimento, magnetismo, eletricidade, ótica, radioatividade e fenômenos relacionados, além de alguma capacidade para construir dispositivos experimentais para testar ideias. O grau de conhecimento depende da era em que o jogo está ambientado. Dispositivos práticos, tais como automóveis, não são a área dos físicos, no entanto, dispositivos experimentais podem ser, talvez em uso conjunto com Eletrônica ou Consertos Mecânicos. Geologia (10%): Usada para determinar a idade aproximada dos estratos de rocha, reconhecer tipos de fósseis, distinguir minerais e cristais, localizar locais promissores para perfuração ou mineração, avaliar solos, antecipar vulcanismo, eventos sísmicos, avalanches e outros fenômenos do tipo. Matemática (01%): O estudo dos números e da lógica, incluindo teorias matemáticas e aplicadas e o desenvolvimento de soluções teóricas. Essa perícia pode permitir identificar geometrias não euclidianas, resolver fórmulas enigmáticas e descriptografar padrões ou códigos complexos (ver Criptografia para o estudo especializado de códigos). Meteorologia (01%): O estudo científico da atmosfera, incluindo sistemas e padrões climáticos, e fenômenos atmosféricos. Use essa perícia para determinar padrões climáticos de longo prazo e efeitos de previsão de tempo como chuva, neve e nevoeiro. Química (01%): Um estudo sobre a composição das substâncias, os efeitos da temperatura, energia e pressão sobre elas, bem como sobre a forma como afetam umas às outras. Usando a química, pode-se criar ou extrair compostos químicos complexos, incluindo explosivos, venenos, gases e ácidos simples, exigindo pelo menos um dia com equipamentos e produtos químicos adequados. O usuário também pode analisar substâncias desconhecidas, com os equipamentos e reagentes adequados. Zoologia (01%): O estudo da biologia que se relaciona especificamente com o reino animal, incluindo a estrutura, evolução, classificação, hábitos comportamentais e distribuição de animais, vivos e extintos. Use essa perícia para identificar espécies de animais a partir da interação com o meio ambiente (pegadas, excrementos, marcas, etc.), prováveis comportamentos e marcas territoriais.
G14: Consertos Elétricos | H14: Consertos Elétricos (10%) Permite consertar ou reconfigurar equipamentos elétricos, como sistemas de ignição elétrica, motores elétricos, caixas de fusíveis e alarmes antirroubo. Nos dias atuais, essa perícia tem pouca relação com Eletrônica. Consertar um dispositivo elétrico pode necessitar de peças ou ferramentas especiais. Na década de 1920, pode ser necessário usar Consertos Mecânicos em associação. Consertos Elétricos também pode ser usada em conjunto com explosivos modernos, como detonadores, explosivos plásticos C-4 e minas. Tais armas são projetadas para serem fáceis de armar; apenas um resultado de desastre fará o artefato explodir (lembre-se de que o teste pode ser Forçado). Desarmar explosivos é muito mais complicado, pois podem ser equipados com mecanismos de segurança; aumente o nível de dificuldade quando essa perícia for utilizada para desarmar explosivos — ver Demolições. Exemplos de testes Forçados: demorar mais para consertar ou reconfigurar o equipamento; tomar um atalho arriscado. Exemplos de fracasso em testes Forçados: receber dano devido a um choque elétrico; explodir os fusíveis e mergulhar o edifício na escuridão; destruir a peça na qual estava trabalhando, para além de qualquer conserto. Se um investigador insano falhar em um teste forçado, ele ou ela tenta canalizar no dispositivo a energia elétrica de organismos vivos.
G15: Consertos Mecânicos | H15: Consertos Mecânicos (10%) Esta perícia permite que o investigador conserte uma máquina quebrada ou crie uma nova. Projetos básicos de carpintaria e encanamento podem ser realizados, bem como a construção de objetos (tal como um sistema de polias) e o conserto de itens (como uma bomba a vapor). Podem ser necessárias ferramentas ou peças especiais. Essa perícia pode ser usada para abrir fechaduras domésticas comuns, mas nada mais avançado do que isso — veja a perícia Chaveiro para fechaduras mais complexas. Consertos Mecânicos é uma perícia que complementa Consertos Elétricos, e ambas podem ser necessárias para consertar dispositivos complexos, como um carro ou uma aeronave. Exemplos de testes Forçados: desmontar o dispositivo completamente; demorar mais tempo; arriscar-se usando força excessiva para ativar o dispositivo (por exemplo, bater no objeto até que funcione). Exemplos de fracasso em testes Forçados: quebrar o dispositivo além de qualquer conserto; machucar-se enquanto trabalha no dispositivo (talvez cortando a mão etc.); ficar obcecado com o dispositivo e perceber que passou o dia e anoite inteiros trabalhando nele. Se um investigador insano falhar em um teste forçado, ele ou ela preenche um caderno de anotações do tamanho de um catálogo telefônico inteiro com rascunhos de projetos, culminando na criação de um dispositivo bizarro que usa matéria orgânica e partes de eletrodomésticos.
G16: Contabilidade | H16: Contabilidade (05%) Concede compreensão dos procedimentos de contabilidade e revela o funcionamento financeiro de uma empresa ou pessoa. Inspecionando os registros, pode-se detectar empregados enganados, fundos desviados, pagamento de subornos ou chantagem, e se a condição financeira real é melhor ou pior do que a reivindicada. Vasculhando contas antigas, é possível determinar como o dinheiro foi ganho ou perdido no passado (grãos, escravização, tráfico de bebidas alcoólicas, etc.) e a quem e por qual motivo pagamentos foram feitos. Exemplos de testes Forçados: gastar mais tempo revisando os documentos; visitar bancos ou empresas para validar descobertas; confrontar os cálculos matemáticos e os dados. Exemplos de fracasso em testes Forçados: as discussões entre os investigadores e terceiros alertam algum grupo inimigo sobre suas intenções; uma parte vital dos registros é destruída ou perdida (talvez, devido ao cansaço, o investigador derrame café sobre eles). Se um investigador insano falhar em um teste forçado, ele ou ela pode ser encontrado comendo os registros de contabilidade.
G17: Demolições | H17: Demolições (01%) [Incomum] Com esta perícia, o usuário tem familiaridade com o emprego seguro de demolições, incluindo armar e neutralizar cargas explosivas. Minas e dispositivos similares são projetados para serem fáceis de instalar (não é necessário um teste), mas são mais difíceis de se remover ou desarmar. Essa perícia também engloba demolições de nível militar (minas terrestres, explosivos plásticos, etc.). Dados tempo e recursos suficientes, aqueles que são proficientes nessa perícia podem instalar explosivos para demolir um edifício, limpar um túnel bloqueado e reutilizar dispositivos explosivos (como para a criação de artefatos de menor potência, armadilhas e outras coisas mais). Exemplos de testes Forçados: ficar até o último segundo tentando desarmar a bomba; fazer dupla verificação, à mão, de todos os circuitos/conexões. Exemplos de fracasso em testes Forçados: se estiver desarmando ou removendo um explosivo, a consequência do fracasso em um teste forçado é clara — ele explode! Se estiver usando a perícia Demolições para armar explosivos, a consequência de falhar em um teste forçado pode ser a detonação não ocorrer no momento esperado (ou jamais acontecer), ou então a detonação falha em ter o efeito desejado (muito forte ou muito fraca). Se um investigador insano falhar um teste forçado, ele ou ela planeja o método mais bizarro de armar o explosivo, como prendê-lo a um gato ou a si próprio.
G18: Dirigir Automóveis | H18: Dirigir Automóveis (20%) Qualquer pessoa com esta perícia pode dirigir um carro ou caminhão leve, fazer manobras comuns e lidar com problemas comuns de veículos. Se o investigador quiser despistar ou perseguir alguém, um teste de Dirigir seria apropriado. Outras culturas podem substituir essa perícia por outra semelhante; os Inuit poderiam usar Dirigir Trenós de Cachorro ou um vitoriano poderia ter Dirigir Carruagens. Exemplos de testes Forçados: forçar os limites do motor; não desacelerar, apesar dos riscos. Exemplos de fracasso em testes Forçados: bater; derrapar e terminar em uma parada brusca, ficando incapaz de prosseguir; ser perseguido pela polícia. Se um investigador insano falhar em um teste forçado, ele ou ela será encontrado ao volante de um veículo parado, fazendo ruídos de motor com a boca.
G19: Direito | H19: Direito (05%) Representa a probabilidade de se conhecer leis, precedentes, manobras legais e procedimentos judiciais pertinentes. A prática do direito enquanto profissão pode levar a grandes recompensas e cargos políticos, mas requer dedicação intensa por muitos anos — um Nível de Crédito elevado geralmente também é crucial nesse sentido. Nos Estados Unidos, a Ordem dos Advogados de um estado ou condado em particular deve sancionar o exercício da profissão. Quando se está em um país estrangeiro, sugere-se que o nível de dificuldade seja aumentado ao usar essa perícia, a menos que o personagem tenha passado muitos meses estudando o sistema legal do lugar em questão. Exemplos de testes Forçados: fazer uma pausa para ponderar sobre seu argumento; explicar com detalhes as nuances do caso/situação; gastar um tempo significativo realizando pesquisas; distorcer a lei para conduzir o seu argumento. Exemplos de fracasso em testes Forçados: interpretar mal uma lei ou sair dos procedimentos legais aceitos levam-no acometer um crime e atrair a atenção da polícia; desperdiçar tempo e dinheiro em pesquisas e honorários legais; ser detido por desacato e jogado na cadeia por pelo menos 24 horas. Se um investigador insano falhar em um teste forçado, ele ou ela acreditará que está acima da lei.
G20: Disfarce | H20: Disfarce (05%) Uma perícia usada sempre que o investigador pretende parecer alguém que ele não é. O usuário muda de postura, roupas e/ou voz para representar o disfarce, passando-se por outra pessoa ou outro tipo de pessoa. Maquiagem teatral pode ajudar, bem como um documento falso. Observe que se passar por uma pessoa específica cara-a cara com alguém que a conhece está além do escopo dessa perícia, e pode indicar a necessidade de um teste combinado de perícias com uma dificuldade maior (com Persuasão, Charme ou Lábia). Exemplos de testes Forçados: passar por uma preparação totalmente imersiva e intensiva (perdendo-se no “papel”); roubar itens pessoais e utilizá-los no disfarce; exagerar ostensivamente na representação, para confundir o alvo; fingir um súbito ataque de alguma doença para desorientar o observador. Exemplos de fracasso em testes Forçados: ser preso; ofender alguém, levando à violência ou acusações criminais; descobrir que a pessoa que está sendo imitada é procurada por uma gangue criminosa que deseja vingança. Se um investigador insano falhar em um teste forçado, o investigador não mais reconhece o seu próprio rosto no espelho, mesmo quando o disfarce for removido.
G21: Escalar | H21: Escalar (20%) Esta perícia possibilita que um personagem escale árvores, paredes e outras superfícies verticais com ou sem cordas e equipamento de escalada. A perícia também abrange o rapel. Condições como a firmeza da superfície, pontos de apoio disponíveis, vento, visibilidade, chuva, etc., podem afetar o nível de dificuldade dos testes. Fracassar no primeiro teste com essa perícia indica que a escalada pode estar além da capacidade do investigador. Falhar em um teste forçado provavelmente indica uma queda que causa dano. Um teste bem sucedido de Escalar, na maioria dos casos, deve permitir que o investigador complete a escalada com sucesso (em vez de exigir repetidos testes). Uma escalada desafiadora ou mais longa deve ter um nível de dificuldade maior. Exemplos de testes Forçados: reavaliar a escalada; tomar uma rota mais longa; esticar-se ao máximo. Exemplos de fracasso em testes Forçados: cair e sofrer dano (1D6 de dano para cada três metros de queda na grama ou 1D10 de dano para cada três metros caindo no concreto); perder um item valioso que cai de seu bolso (podendo não notar até mais tarde); ficar preso, incapaz de subir ou descer. Se um investigador insano falhar em um teste forçado, ele ou ela pode se segurar com todas as forças em algo enquanto grita desesperadamente tanto quanto pode.
